<mujoco model="KR7108-URDF">
  <compiler angle="radian" meshdir="../meshes/gen3lite/" autolimits="true"/>
  <option gravity="0 0 0" integrator="implicitfast" timestep="0.01"/>
  <default>
    <default class="body">
      <geom material="body"/>
    </default>
  </default>
  <asset>
    <texture type="skybox" builtin="gradient" rgb1=".3 .5 .7" rgb2="0 0 0" width="512" height="512"/>
    <texture name="grid" type="2d" builtin="checker" width="512" height="512" rgb1=".1 .2 .3" rgb2=".2 .3 .4"/>
    <material name="grid" texture="grid" texrepeat="1 1" texuniform="true" reflectance=".2"/>
    <texture name="body" type="cube" builtin="flat" mark="cross" width="127" height="1278" rgb1="0.9 0.9 0.9" rgb2="1 1 1" markrgb="0.8 0.8 0.8" random="0.01"/>
    <material name="body" texture="body" texuniform="true" rgba="0.8 0.8 0.8 1"/>
    <mesh name="BASE" file="base_link.STL"/>
    <mesh name="SHOULDER" file="shoulder_link.STL"/>
    <mesh name="ARM" file="arm_link.STL"/>
    <mesh name="FOREARM" file="forearm_link.STL"/>
    <mesh name="LOWER_WRIST" file="lower_wrist_link.STL"/>
    <mesh name="UPPER_WRIST" file="upper_wrist_link.STL"/>
  </asset>
  <worldbody>
    <geom name="floor" size="0 0 .05" type="plane" material="grid" condim="3"/>
    <light pos="0 0 5" dir="0 0 -1" diffuse="1 1 1"/>
    <body name="BASE" pos="0 0 0" quat="1 0 0 0" gravcomp="0" childclass="body">
      <geom type="mesh" mesh="BASE"/>
      <body name="SHOULDER" pos="0 0 0.12825" gravcomp="0">
        <inertial pos="2.477e-05 0.0221353 0.0993769" quat="0.972429 0.233194 -0.000430944 0.00108761" mass="0.959744" diaginertia="0.00165947 0.00158128 0.000717195"/>
        <joint name="0" pos="0 0 0" axis="0 0 1" range="-2.76 2.76" frictionloss="0.2" armature="0"/>
        <geom type="mesh" mesh="SHOULDER"/>
        <body name="ARM" pos="0 -0.03 0.115" quat="0.707105 0.707108 0 0" gravcomp="0">
          <inertial pos="0 0.211548 0.0453031" quat="0.534676 0.467794 -0.46336 0.529706" mass="1.17756" diaginertia="0.0115237 0.0114928 0.000839712"/>
          <joint name="1" pos="0 0 0" axis="0 0 1" range="-2.76 2.76" frictionloss="0.2" armature="0"/>
          <geom type="mesh" mesh="ARM"/>
          <body name="FOREARM" pos="0 0.28 0" quat="-3.67321e-06 -1 0 0" gravcomp="0">
            <inertial pos="0 -0.0950221 0.0073555" quat="0.523543 0.49139 -0.473675 0.50997" mass="0.597677" diaginertia="0.00169754 0.00163253 0.000291376"/>
            <joint name="2" pos="0 0 0" axis="0 0 1" range="-2.76 2.76" frictionloss="0.2" armature="0"/>
            <geom type="mesh" mesh="FOREARM"/>
            <body name="LOWER_WRIST" pos="0 -0.14 0.02" quat="0.707105 0.707108 0 0" gravcomp="0">
              <inertial pos="0.00575149 0 0.0871921" quat="0.6985 0.142264 0.143914 0.686402" mass="0.526934" diaginertia="0.000785199 0.000756398 0.000275722"/>
              <joint name="3" pos="0 0 0" axis="0 0 1" range="-2.67 2.67" frictionloss="0.2" armature="0"/>
              <geom type="mesh" mesh="LOWER_WRIST"/>
              <body name="UPPER_WRIST" pos="0.0285 0 0.105" quat="0.707105 0 0.707108 0" gravcomp="0">
                <inertial pos="-0.0805652 0 0.018728" quat="0.00431726 0.708285 -4.18922e-06 0.705913" mass="0.580973" diaginertia="0.00108466 0.00106374 0.000212638"/>
                <joint name="4" pos="0 0 0" axis="0 0 1" range="-2.67 2.67" frictionloss="0.2" armature="0"/>
                <geom type="mesh" mesh="UPPER_WRIST"/>
                <body name="GRIPPER_FRAME" pos="-0.105 0 0.0285" quat="0.707105 0 -0.707108 0" gravcomp="0">
                  <inertial pos="6.65981e-06 7.47078e-06 0.0547856" quat="1 0.000127331 -6.00906e-06 2.46989e-05" mass="0.197766" diaginertia="0.000265651 0.000216392 0.00013346"/>
                  <joint name="5" pos="0 0 0" axis="0 0 1" range="-2.67 2.67" frictionloss="0.2" armature="0"/>
                  <site type="sphere" pos="0 0 0.09" size="0.01" rgba="0 0 1 1"/>
                </body>
              </body>
            </body>
          </body>
        </body>
      </body>
    </body>
  </worldbody>
  <actuator>
    <velocity joint="0" ctrlrange="-2.0 2.0" kv='100' ctrllimited="true" />
    <velocity joint="1" ctrlrange="-2.0 2.0" kv='100' ctrllimited="true" />
    <velocity joint="2" ctrlrange="-2.0 2.0" kv='90' ctrllimited="true" />
    <velocity joint="3" ctrlrange="-2.0 2.0" kv='80' ctrllimited="true" />
    <velocity joint="4" ctrlrange="-2.0 2.0" kv='70' ctrllimited="true" />
    <velocity joint="5" ctrlrange="-2.0 2.0" kv='50' ctrllimited="true" />
  </actuator>
</mujoco>
