<?xml version="1.0" ?>
<!-- =================================================================================== -->
<!-- |    This document was autogenerated by xacro from dingo_full.urdf.xacro          | -->
<!-- |    EDITING THIS FILE BY HAND IS NOT RECOMMENDED                                 | -->
<!-- | Made omnidirectional by using prismatic joints w.r.t world frame by Andreu      | -->
<!-- =================================================================================== -->
<robot name="dingo_kinova">
  <material name="dark_grey">
    <color rgba="0.2 0.2 0.2 1.0"/>
  </material>
  <material name="light_grey">
    <color rgba="0.4 0.4 0.4 1.0"/>
  </material>
  <material name="yellow">
    <color rgba="0.8 0.8 0.0 1.0"/>
  </material>
  <material name="black">
    <color rgba="0.15 0.15 0.15 1.0"/>
  </material>
  <link name="world"/>
  <link name="base_link_x">
    <inertial>
      <mass value="1.0"/>
      <origin rpy="0 0 0" xyz="0 0 0"/>
      <inertia ixx="1.0" ixy="0.0" ixz="0.0" iyy="1.0" iyz="0.0" izz="1.0"/>
    </inertial>
  </link>
  <link name="base_link_y">
    <inertial>
      <mass value="1.0"/>
      <origin rpy="0 0 0" xyz="0 0 0"/>
      <inertia ixx="1.0" ixy="0.0" ixz="0.0" iyy="1.0" iyz="0.0" izz="1.0"/>
    </inertial>
  </link>
  <joint name="omni_joint_x" type="prismatic">
    <safety_controller k_position="100.0" k_velocity="40.0" soft_lower_limit="-500" soft_upper_limit="500"/>
    <parent link="world"/>
    <child link="base_link_x"/>
    <origin rpy="0 0 0" xyz="0 0 0.03"/>
    <axis xyz="1 0 0"/>
    <dynamics damping="100.0"/>
    <limit effort="1000" lower="-10" upper="10" velocity="2" stiffness="1000"/>
  </joint>
  <joint name="omni_joint_y" type="prismatic">
    <safety_controller k_position="100.0" k_velocity="40.0" soft_lower_limit="-500" soft_upper_limit="500"/>
    <parent link="base_link_x"/>
    <child link="base_link_y"/>
    <origin rpy="0 0 0" xyz="0 0 0"/>
    <axis xyz="0 1 0"/>
    <dynamics damping="100.0"/>
    <limit effort="1000" lower="-10" upper="10" velocity="2" stiffness="1000"/>
  </joint>
  <joint name="omni_joint_theta" type="revolute">
    <safety_controller k_position="100.0" k_velocity="40.0" soft_lower_limit="-500" soft_upper_limit="500"/>
    <parent link="base_link_y"/>
    <child link="base_link"/>
    <origin rpy="0 0 0" xyz="0 0 0"/>
    <axis xyz="0 0 1"/>
    <dynamics damping="100.0"/>
    <limit effort="1000" lower="-6.283184 " upper="6.283184" velocity="2" stiffness="1000"/>
  </joint>
  <link name="base_link"/>
  <joint name="base_link_joint" type="fixed">
    <origin rpy="0 0 0" xyz="0 0 0"/>
    <parent link="base_link"/>
    <child link="chassis_link"/>
  </joint>
  <link name="front_left_wheel_link">
    <visual>
      <origin rpy="1.5707963267948966 0 0" xyz="0 0 0"/>
      <geometry>
        <cylinder length="0.05" radius="0.05"/>
      </geometry>
      <material name="black"/>
    </visual>
    <!-- <collision>
      <origin rpy="1.5707963267948966 0 0" xyz="0 0 0"/>
      <geometry>
        <cylinder length="0.05" radius="0.05"/>
      </geometry>
    </collision> -->
    <inertial>
      <origin rpy="0 0 0" xyz="0 0 0"/>
      <mass value="0.4"/>
      <inertia ixx="0.0003234" ixy="0" ixz="0" iyy="0.0003234" iyz="0" izz="0.0004901"/>
    </inertial>
  </link>
  <joint name="front_left_wheel" type="fixed">
    <parent link="chassis_link"/>
    <child link="front_left_wheel_link"/>
    <origin rpy="0 0 0" xyz="0.285 0.2104 0.035145"/>
    <axis xyz="0 1 0"/>
  </joint>
  <link name="front_right_wheel_link">
    <visual>
      <origin rpy="1.5707963267948966 0 0" xyz="0 0 0"/>
      <geometry>
        <cylinder length="0.05" radius="0.05"/>
      </geometry>
      <material name="black"/>
    </visual>
    <!-- <collision>
      <origin rpy="1.5707963267948966 0 0" xyz="0 0 0"/>
      <geometry>
        <cylinder length="0.05" radius="0.05"/>
      </geometry>
    </collision> -->
    <inertial>
      <origin rpy="0 0 0" xyz="0 0 0"/>
      <mass value="0.4"/>
      <inertia ixx="0.0003234" ixy="0" ixz="0" iyy="0.0003234" iyz="0" izz="0.0004901"/>
    </inertial>
  </link>
  <joint name="front_right_wheel" type="fixed">
    <parent link="chassis_link"/>
    <child link="front_right_wheel_link"/>
    <origin rpy="0 0 0" xyz="0.285 -0.2104 0.035145"/>
    <axis xyz="0 1 0"/>
  </joint>
  <link name="rear_left_wheel_link">
    <visual>
      <origin rpy="1.5707963267948966 0 0" xyz="0 0 0"/>
      <geometry>
        <cylinder length="0.05" radius="0.05"/>
      </geometry>
      <material name="black"/>
    </visual>
    <!-- <collision>
      <origin rpy="1.5707963267948966 0 0" xyz="0 0 0"/>
      <geometry>
        <cylinder length="0.05" radius="0.05"/>
      </geometry>
    </collision> -->
    <inertial>
      <origin rpy="0 0 0" xyz="0 0 0"/>
      <mass value="0.4"/>
      <inertia ixx="0.0003234" ixy="0" ixz="0" iyy="0.0003234" iyz="0" izz="0.0004901"/>
    </inertial>
  </link>
  <joint name="rear_left_wheel" type="fixed">
    <parent link="chassis_link"/>
    <child link="rear_left_wheel_link"/>
    <origin rpy="0 0 0" xyz="-0.285 0.2104 0.035145"/>
    <axis xyz="0 1 0"/>
  </joint>
  <link name="rear_right_wheel_link">
    <visual>
      <origin rpy="1.5707963267948966 0 0" xyz="0 0 0"/>
      <geometry>
        <cylinder length="0.05" radius="0.05"/>
      </geometry>
      <material name="black"/>
    </visual>
    <!-- <collision>
      <origin rpy="1.5707963267948966 0 0" xyz="0 0 0"/>
      <geometry>
        <cylinder length="0.05" radius="0.05"/>
      </geometry>
    </collision> -->
    <inertial>
      <origin rpy="0 0 0" xyz="0 0 0"/>
      <mass value="0.4"/>
      <inertia ixx="0.0003234" ixy="0" ixz="0" iyy="0.0003234" iyz="0" izz="0.0004901"/>
    </inertial>
  </link>
  <joint name="rear_right_wheel" type="fixed">
    <parent link="chassis_link"/>
    <child link="rear_right_wheel_link"/>
    <origin rpy="0 0 0" xyz="-0.285 -0.2104 0.035145"/>
    <axis xyz="0 1 0"/>
  </joint>
  <link name="chassis_link">
    <visual>
      <origin rpy="1.570796 0 0" xyz="0 0 0"/>
      <geometry>
        <!-- <mesh filename="../meshes/base/omni_chassis.dae"/> -->
        <mesh filename="../meshes/base/omni_chassis_collision.stl"/>
      </geometry>
      <material name="dark_grey"/>
      <!-- <material name="yellow"/> -->
    </visual>
    <collision>
      <origin xyz="0 0 0"/>
      <geometry>
        <mesh filename="../meshes/base/omni_chassis_collision.stl"/>
      </geometry>
    </collision>
    <inertial>
      <!-- Center of mass -->
      <origin rpy="0 0 0" xyz="0 0 0"/>
      <mass value="14"/>
      <!-- Moments of inertia: ( chassis without wheels ) -->
      <inertia ixx="0.35498" ixy="0" ixz="0" iyy="0.7266" iyz="0" izz="1.0553"/>
    </inertial>
  </link>
  <link name="imu_link">
    <inertial>
      <mass value="0.001"/>
      <origin rpy="0 0 0" xyz="0 0 0"/>
      <inertia ixx="1e-09" ixy="0.0" ixz="0.0" iyy="1e-09" iyz="0.0" izz="1e-09"/>
    </inertial>
  </link>
  <joint name="imu_joint" type="fixed">
    <parent link="chassis_link"/>
    <child link="imu_link"/>
  </joint>
  <!--
    Mounting points for accessories in the top channel.
    These are flush with the top of the robot and all oriented to face forwards.
    Dingo-D has 6 evenly-spaced 80mm mounts
    We name the mounts (from front to back)
      - front
      - front b
      - front c
      - mid
      - rear c
      - rear b
      - rear
  -->
  <link name="front_mount"/>
  <link name="front_b_mount"/>
  <link name="front_c_mount"/>
  <link name="rear_mount"/>
  <link name="rear_b_mount"/>
  <link name="rear_c_mount"/>
  <link name="mid_mount"/>
  <joint name="mid_mount_joint" type="fixed">
    <origin rpy="0 0 0" xyz="0 0 0.069023"/>
    <parent link="chassis_link"/>
    <child link="mid_mount"/>
  </joint>
  <joint name="front_c_mount_joint" type="fixed">
    <origin rpy="0 0 0" xyz="0.080 0 0"/>
    <parent link="mid_mount"/>
    <child link="front_c_mount"/>
  </joint>
  <joint name="front_b_mount_joint" type="fixed">
    <origin rpy="0 0 0" xyz="0.080 0 0"/>
    <parent link="front_c_mount"/>
    <child link="front_b_mount"/>
  </joint>
  <joint name="front_mount_joint" type="fixed">
    <origin rpy="0 0 0" xyz="0.080 0 0"/>
    <parent link="front_b_mount"/>
    <child link="front_mount"/>
  </joint>
  <joint name="rear_c_mount_joint" type="fixed">
    <origin rpy="0 0 0" xyz="-0.080 0 0"/>
    <parent link="mid_mount"/>
    <child link="rear_c_mount"/>
  </joint>
  <joint name="rear_b_mount_joint" type="fixed">
    <origin rpy="0 0 0" xyz="-0.080 0 0"/>
    <parent link="rear_c_mount"/>
    <child link="rear_b_mount"/>
  </joint>
  <joint name="rear_moint_joint" type="fixed">
    <origin rpy="0 0 0" xyz="-0.080 0 0"/>
    <parent link="rear_b_mount"/>
    <child link="rear_mount"/>
  </joint>
  <!--
    Mounting point for accessories on the front bumper.
    Use with caution, but thin sensors (e.g Raspberry Pi NoIR camera) could
    be mounted here for low-budget, front/rear-facing capabilities
  -->
  <link name="front_bumper_mount"/>
  <joint name="front_bumper_mount_joint" type="fixed">
    <origin rpy="0 0 0" xyz="0.34159 0 0.0345115"/>
    <parent link="chassis_link"/>
    <child link="front_bumper_mount"/>
  </joint>
  <gazebo>
    <plugin filename="libgazebo_ros_control.so" name="gazebo_ros_control">
      <robotNamespace>/</robotNamespace>
    </plugin>
  </gazebo>
  <gazebo>
    <plugin filename="libhector_gazebo_ros_imu.so" name="imu_controller">
      <robotNamespace>/</robotNamespace>
      <updateRate>50.0</updateRate>
      <bodyName>imu_link</bodyName>
      <topicName>imu/data</topicName>
      <accelDrift>0.005 0.005 0.005</accelDrift>
      <accelGaussianNoise>0.005 0.005 0.005</accelGaussianNoise>
      <rateDrift>0.005 0.005 0.005 </rateDrift>
      <rateGaussianNoise>0.005 0.005 0.005 </rateGaussianNoise>
      <headingDrift>0.005</headingDrift>
      <headingGaussianNoise>0.005</headingGaussianNoise>
    </plugin>
  </gazebo>
  <gazebo reference="base_link">
    <turnGravityOff>false</turnGravityOff>
  </gazebo>
  <gazebo reference="chassis_link">
    <turnGravityOff>false</turnGravityOff>
  </gazebo>
  <gazebo reference="imu_link">
    <turnGravityOff>false</turnGravityOff>
  </gazebo>
  <gazebo>
    <plugin filename="libridgeback_ros_force_based_move.so" name="dingo_ros_force_based_move">
      <robotNamespace>/</robotNamespace>
      <commandTopic>dingo_velocity_controller/cmd_vel</commandTopic>
      <odometryTopic>odom</odometryTopic>
      <odometryFrame>odom</odometryFrame>
      <odometryRate>50.0</odometryRate>
      <robotBaseFrame>base_link</robotBaseFrame>
      <cmdVelTimeOut>0.25</cmdVelTimeOut>
      <!-- Don't publish a transform: the controller does it. -->
      <publishOdometryTf>0</publishOdometryTf>
      <yaw_velocity_p_gain>500.0</yaw_velocity_p_gain>
      <x_velocity_p_gain>10000.0</x_velocity_p_gain>
      <y_velocity_p_gain>10000.0</y_velocity_p_gain>
    </plugin>
  </gazebo>
  <gazebo reference="front_left_wheel_link">
    <material>Gazebo/DarkGrey</material>
    <mu1>0.0</mu1>
    <mu2>0.0</mu2>
  </gazebo>
  <gazebo reference="front_right_wheel_link">
    <material>Gazebo/DarkGrey</material>
    <mu1>0.0</mu1>
    <mu2>0.0</mu2>5
  </gazebo>
  <gazebo reference="rear_left_wheel_link">
    <material>Gazebo/DarkGrey</material>
    <mu1>0.0</mu1>
    <mu2>0.0</mu2>
  </gazebo>
  <gazebo reference="rear_right_wheel_link">
    <material>Gazebo/DarkGrey</material>
    <mu1>0.0</mu1>
    <mu2>0.0</mu2>
  </gazebo>

  <!-- URDF of the KINOVA arm from the official repo https://github.com/Kinovarobotics/ros_kortex/blob/noetic-devel/kortex_description/readme.md -->
  <link name="base_link">
    <inertial>
      <origin xyz="-0.000648 -0.000166 0.084487" rpy="0 0 0" />
      <mass value="1.697" />
      <inertia ixx="0.004622" ixy="9E-06" ixz="6E-05" iyy="0.004495" iyz="9E-06" izz="0.002079" />
    </inertial>
    <visual>
      <origin xyz="0 0 0" rpy="0 0 0" />
      <geometry>
        <mesh filename="../meshes/gen3_6dof/base_link.STL" />
      </geometry>
      <material name="">
        <color rgba="0.75294 0.75294 0.75294 1" />
      </material>
    </visual>
    <collision>
      <origin xyz="0 0 0" rpy="0 0 0" />
      <geometry>
        <mesh filename="../meshes/gen3_6dof/base_link.STL" />
      </geometry>
    </collision>
  <joint name="arm_mount_joint" type="fixed">
    <origin rpy="0 0 0" xyz="0.0 0.0 0.0"/>
    <parent link="front_b_mount"/>
    <child link="base_link"/>
  </joint>
  </link>
  <link name="shoulder_link">
    <inertial>
      <origin xyz="-2.3E-05 -0.010364 -0.07336" rpy="0 0 0" />
      <mass value="1.377" />
      <inertia ixx="0.00457" ixy="1E-06" ixz="2E-06" iyy="0.004831" iyz="0.000448" izz="0.001409" />
    </inertial>
    <visual>
      <origin xyz="0 0 0" rpy="0 0 0" />
      <geometry>
        <mesh filename="../meshes/gen3_6dof/shoulder_link.STL" />
      </geometry>
      <material name="">
        <color rgba="0.75294 0.75294 0.75294 1" />
      </material>
    </visual>
    <collision>
      <origin xyz="0 0 0" rpy="0 0 0" />
      <geometry>
        <mesh filename="../meshes/gen3_6dof/shoulder_link.STL" />
      </geometry>
    </collision>
  </link>
  <joint name="joint_1" type="continuous">
    <origin xyz="0 0 0.15643" rpy="-3.1416 0 0" />
    <parent link="base_link" />
    <child link="shoulder_link" />
    <axis xyz="0 0 1" />
    <limit effort="39" velocity="1.3963" />
  </joint>
  <link name="bicep_link">
    <inertial>
      <origin xyz="3.5E-05 -0.208207 -0.01889" rpy="0 0 0" />
      <mass value="1.262" />
      <inertia ixx="0.046752" ixy="-9E-06" ixz="0" iyy="0.00085" iyz="-9.8E-05" izz="0.047188" />
    </inertial>
    <visual>
      <origin xyz="0 0 0" rpy="0 0 0" />
      <geometry>
        <mesh filename="../meshes/gen3_6dof/bicep_link.STL" />
      </geometry>
      <material name="">
        <color rgba="0.75294 0.75294 0.75294 1" />
      </material>
    </visual>
    <collision>
      <origin xyz="0 0 0" rpy="0 0 0" />
      <geometry>
        <mesh filename="../meshes/gen3_6dof/bicep_link.STL" />
      </geometry>
    </collision>
  </link>
  <joint name="joint_2" type="revolute">
    <origin xyz="0 0.005375 -0.12838" rpy="1.5708 0 0" />
    <parent link="shoulder_link" />
    <child link="bicep_link" />
    <axis xyz="0 0 1" />
    <limit lower="-2.24" upper="2.24" effort="39" velocity="1.3963" />
  </joint>
  <link name="forearm_link">
    <inertial>
      <origin xyz="1.8E-05 0.076168 -0.01397" rpy="0 0 0" />
      <mass value="0.93" />
      <inertia ixx="0.008292" ixy="-1E-06" ixz="0" iyy="0.000628" iyz="0.000432" izz="0.008464" />
    </inertial>
    <visual>
      <origin xyz="0 0 0" rpy="0 0 0" />
      <geometry>
        <mesh filename="../meshes/gen3_6dof/forearm_link.STL" />
      </geometry>
      <material name="">
        <color rgba="0.75294 0.75294 0.75294 1" />
      </material>
    </visual>
    <collision>
      <origin xyz="0 0 0" rpy="0 0 0" />
      <geometry>
        <mesh filename="../meshes/gen3_6dof/forearm_link.STL" />
      </geometry>
    </collision>
  </link>
  <joint name="joint_3" type="revolute">
    <origin xyz="0 -0.41 0" rpy="3.1416 0 0" />
    <parent link="bicep_link" />
    <child link="forearm_link" />
    <axis xyz="0 0 1" />
    <limit lower="-2.57" upper="2.57" effort="39" velocity="1.3963" />
  </joint>
  <link name="spherical_wrist_1_link">
    <inertial>
      <origin xyz="-1E-06 0.008486 -0.062937" rpy="0 0 0" />
      <mass value="0.678" />
      <inertia ixx="0.001645" ixy="0" ixz="0" iyy="0.001666" iyz="-0.000234" izz="0.000389" />
    </inertial>
    <visual>
      <origin xyz="0 0 0" rpy="0 0 0" />
      <geometry>
        <mesh filename="../meshes/gen3_6dof/spherical_wrist_1_link.STL" />
      </geometry>
      <material name="">
        <color rgba="0.75294 0.75294 0.75294 1" />
      </material>
    </visual>
    <collision>
      <origin xyz="0 0 0" rpy="0 0 0" />
      <geometry>
        <mesh filename="../meshes/gen3_6dof/spherical_wrist_1_link.STL" />
      </geometry>
    </collision>
  </link>
  <joint name="joint_4" type="continuous">
    <origin xyz="0 0.20843 -0.006375" rpy="1.5708 0 0" />
    <parent link="forearm_link" />
    <child link="spherical_wrist_1_link" />
    <axis xyz="0 0 1" />
    <limit effort="9" velocity="1.2218" />
  </joint>
  <link name="spherical_wrist_2_link">
    <inertial>
      <origin xyz="-1E-06 0.046429 -0.008704" rpy="0 0 0" />
      <mass value="0.678" />
      <inertia ixx="0.001685" ixy="0" ixz="0" iyy="0.0004" iyz="0.000255" izz="0.001696" />
    </inertial>
    <visual>
      <origin xyz="0 0 0" rpy="0 0 0" />
      <geometry>
        <mesh filename="../meshes/gen3_6dof/spherical_wrist_2_link.STL" />
      </geometry>
      <material name="">
        <color rgba="0.75294 0.75294 0.75294 1" />
      </material>
    </visual>
    <collision>
      <origin xyz="0 0 0" rpy="0 0 0" />
      <geometry>
        <mesh filename="../meshes/gen3_6dof/spherical_wrist_2_link.STL" />
      </geometry>
    </collision>
  </link>
  <joint name="joint_5" type="revolute">
    <origin xyz="0 -0.00017505 -0.10593" rpy="-1.5708 0 0" />
    <parent link="spherical_wrist_1_link" />
    <child link="spherical_wrist_2_link" />
    <axis xyz="0 0 1" />
    <limit lower="-2.09" upper="2.09" effort="9" velocity="1.2218" />
  </joint>
  <link name="bracelet_link">
    <inertial>
      <origin xyz="-9.3E-05 0.000132 -0.022905" rpy="0 0 0" />
      <mass value="0.364" />
      <inertia ixx="0.000214" ixy="0" ixz="1E-06" iyy="0.000223" iyz="-2E-06" izz="0.00024" />
    </inertial>
    <visual>
      <origin xyz="0 0 0" rpy="0 0 0" />
      <geometry>
        <mesh filename="../meshes/gen3_6dof/bracelet_no_vision_link.STL" />
      </geometry>
      <material name="">
        <color rgba="0.75294 0.75294 0.75294 1" />
      </material>
    </visual>
    <collision>
      <origin xyz="0 0 0" rpy="0 0 0" />
      <geometry>
        <mesh filename="../meshes/gen3_6dof/bracelet_no_vision_link.STL" />
      </geometry>
    </collision>
  </link>
  <joint name="joint_6" type="continuous">
    <origin xyz="0 0.10593 -0.00017505" rpy="1.5708 0 0" />
    <parent link="spherical_wrist_2_link" />
    <child link="bracelet_link" />
    <axis xyz="0 0 1" />
    <limit effort="9" velocity="1.2218" />
  </joint>
  <link name="end_effector_link">
    <inertial>
      <origin xyz="0 0 0" rpy="0 0 0" />
      <mass value="0" />
      <inertia ixx="0" ixy="0" ixz="0" iyy="0" iyz="0" izz="0" />
    </inertial>
  </link>
  <joint name="end_effector" type="fixed">
    <origin xyz="0 0 -0.061525" rpy="3.1416 0 -3.1416" />
    <parent link="bracelet_link" />
    <child link="end_effector_link" />
    <axis xyz="0 0 0" />
  </joint>
</robot>
